<mujoco model="ur5e">
  <compiler angle="radian" meshdir="assets/" autolimits="true"/>
  <option integrator="implicitfast"/>
  <size nkey="1"/>
  <statistic meansize="0.251629" extent="1.98587" center="-0.284064 -0.0781146 0.02269"/>
  <default class="main">
    <default class="ur5e">
      <material shininess="0.25"/>
      <joint range="-6.28319 6.28319" armature="0.1"/>
      <site size="0.001 0.005 0.005" group="4" rgba="0.5 0.5 0.5 0.3"/>
      <general ctrlrange="-6.2831 6.2831" forcerange="-150 150" biastype="affine" gainprm="2000 0 0 0 0 0 0 0 0 0" biasprm="0 -2000 -400 0 0 0 0 0 0 0"/>
      <default class="size3">
        <default class="size3_limited">
          <joint range="-3.1415 3.1415"/>
          <general ctrlrange="-3.1415 3.1415"/>
        </default>
      </default>
      <default class="size1">
        <general forcerange="-28 28" gainprm="500 0 0 0 0 0 0 0 0 0" biasprm="0 -500 -100 0 0 0 0 0 0 0"/>
      </default>
      <default class="visual">
        <geom type="mesh" contype="0" conaffinity="0" group="2"/>
      </default>
      <default class="collision">
        <geom type="capsule" group="3"/>
        <default class="eef_collision">
          <geom type="cylinder"/>
        </default>
      </default>
    </default>
  </default>
  <asset>
    <material name="black" class="ur5e" rgba="0.033 0.033 0.033 1"/>
    <material name="jointgray" class="ur5e" rgba="0.278 0.278 0.278 1"/>
    <material name="linkgray" class="ur5e" rgba="0.82 0.82 0.82 1"/>
    <material name="urblue" class="ur5e" rgba="0.49 0.678 0.8 1"/>
    <material name="table"/>
    <material name="glass" rgba="0.8 0.8 0.9 0.5"/>
    <mesh name="base_0" file="base_0.obj"/>
    <mesh name="base_1" file="base_1.obj"/>
    <mesh name="shoulder_0" file="shoulder_0.obj"/>
    <mesh name="shoulder_1" file="shoulder_1.obj"/>
    <mesh name="shoulder_2" file="shoulder_2.obj"/>
    <mesh name="upperarm_0" file="upperarm_0.obj"/>
    <mesh name="upperarm_1" file="upperarm_1.obj"/>
    <mesh name="upperarm_2" file="upperarm_2.obj"/>
    <mesh name="upperarm_3" file="upperarm_3.obj"/>
    <mesh name="forearm_0" file="forearm_0.obj"/>
    <mesh name="forearm_1" file="forearm_1.obj"/>
    <mesh name="forearm_2" file="forearm_2.obj"/>
    <mesh name="forearm_3" file="forearm_3.obj"/>
    <mesh name="wrist1_0" file="wrist1_0.obj"/>
    <mesh name="wrist1_1" file="wrist1_1.obj"/>
    <mesh name="wrist1_2" file="wrist1_2.obj"/>
    <mesh name="wrist2_0" file="wrist2_0.obj"/>
    <mesh name="wrist2_1" file="wrist2_1.obj"/>
    <mesh name="wrist2_2" file="wrist2_2.obj"/>
    <mesh name="wrist3" file="wrist3.obj"/>
  </asset>
  <worldbody>
    <light name="spotlight" target="wrist_2_link" pos="0 -1 2" dir="0 0 -1" mode="targetbodycom"/>
    <body name="table">
      <geom size="0.5 0.5 0.05" type="box" material="table" rgba="1 1 1 1"/>
    </body>
    <body name="glass" pos="0.2 0 0.15">
      <joint type="free"/>
      <geom size="0.04 0.1" type="cylinder" friction="0.9 0.1 0.1" mass="0.2" material="glass" rgba="0.8 0.8 0.9 0.5"/>
    </body>
    <body name="base" childclass="ur5e" pos="-0.35 -0.4 0.3" quat="0 0 0 -1">
      <inertial pos="0 0 0" mass="4" diaginertia="0.00443333 0.00443333 0.0072"/>
      <geom class="visual" material="black" mesh="base_0"/>
      <geom class="visual" material="jointgray" mesh="base_1"/>
      <body name="shoulder_link" pos="0 0 0.163">
        <inertial pos="0 0 0" mass="3.7" diaginertia="0.0102675 0.0102675 0.00666"/>
        <joint name="shoulder_pan_joint" class="size3" pos="0 0 0" axis="0 0 1"/>
        <geom class="visual" material="urblue" mesh="shoulder_0"/>
        <geom class="visual" material="black" mesh="shoulder_1"/>
        <geom class="visual" material="jointgray" mesh="shoulder_2"/>
        <geom class="collision" size="0.06 0.06" pos="0 0 -0.04"/>
        <body name="upper_arm_link" pos="0 0.138 0" quat="0.707107 0 0.707107 0">
          <inertial pos="0 0 0.2125" mass="8.393" diaginertia="0.133886 0.133886 0.0151074"/>
          <joint name="shoulder_lift_joint" class="size3" pos="0 0 0" axis="0 1 0"/>
          <geom class="visual" material="linkgray" mesh="upperarm_0"/>
          <geom class="visual" material="black" mesh="upperarm_1"/>
          <geom class="visual" material="jointgray" mesh="upperarm_2"/>
          <geom class="visual" material="urblue" mesh="upperarm_3"/>
          <geom class="collision" size="0.06 0.06" pos="0 -0.04 0" quat="0.707107 0.707107 0 0"/>
          <geom class="collision" size="0.05 0.2" pos="0 0 0.2"/>
          <body name="forearm_link" pos="0 -0.131 0.425">
            <inertial pos="0 0 0.196" mass="2.275" diaginertia="0.0311796 0.0311796 0.004095"/>
            <joint name="elbow_joint" class="size3_limited" pos="0 0 0" axis="0 1 0"/>
            <geom class="visual" material="urblue" mesh="forearm_0"/>
            <geom class="visual" material="linkgray" mesh="forearm_1"/>
            <geom class="visual" material="black" mesh="forearm_2"/>
            <geom class="visual" material="jointgray" mesh="forearm_3"/>
            <geom class="collision" size="0.055 0.06" pos="0 0.08 0" quat="0.707107 0.707107 0 0"/>
            <geom class="collision" size="0.038 0.19" pos="0 0 0.2"/>
            <body name="wrist_1_link" pos="0 0 0.392" quat="0.707107 0 0.707107 0">
              <inertial pos="0 0.127 0" mass="1.219" diaginertia="0.0025599 0.0025599 0.0021942"/>
              <joint name="wrist_1_joint" class="size1" pos="0 0 0" axis="0 1 0"/>
              <geom class="visual" material="black" mesh="wrist1_0"/>
              <geom class="visual" material="urblue" mesh="wrist1_1"/>
              <geom class="visual" material="jointgray" mesh="wrist1_2"/>
              <geom class="collision" size="0.04 0.07" pos="0 0.05 0" quat="0.707107 0.707107 0 0"/>
              <body name="wrist_2_link" pos="0 0.127 0">
                <inertial pos="0 0 0.1" mass="1.219" diaginertia="0.0025599 0.0025599 0.0021942"/>
                <joint name="wrist_2_joint" class="size1" pos="0 0 0" axis="0 0 1"/>
                <geom class="visual" material="black" mesh="wrist2_0"/>
                <geom class="visual" material="urblue" mesh="wrist2_1"/>
                <geom class="visual" material="jointgray" mesh="wrist2_2"/>
                <geom class="collision" size="0.04 0.06" pos="0 0 0.04"/>
                <geom class="collision" size="0.04 0.04" pos="0 0.02 0.1" quat="0.707107 0.707107 0 0"/>
                <body name="wrist_3_link" pos="0 0 0.1">
                  <inertial pos="0 0.0771683 0" quat="0.707107 0 0 0.707107" mass="0.1889" diaginertia="0.000132134 9.90863e-05 9.90863e-05"/>
                  <joint name="wrist_3_joint" class="size1" pos="0 0 0" axis="0 1 0"/>
                  <geom class="visual" material="linkgray" mesh="wrist3"/>
                  <geom class="eef_collision" size="0.04 0.02" pos="0 0.08 0" quat="0.707107 0.707107 0 0"/>
                  <site name="attachment_site" pos="0 0.1 0" quat="-0.707107 0.707107 0 0"/>
                </body>
              </body>
            </body>
          </body>
        </body>
      </body>
    </body>
  </worldbody>
  <actuator>
    <general name="shoulder_pan" class="size3" joint="shoulder_pan_joint"/>
    <general name="shoulder_lift" class="size3" joint="shoulder_lift_joint"/>
    <general name="elbow" class="size3_limited" joint="elbow_joint"/>
    <general name="wrist_1" class="size1" joint="wrist_1_joint"/>
    <general name="wrist_2" class="size1" joint="wrist_2_joint"/>
    <general name="wrist_3" class="size1" joint="wrist_3_joint"/>
  </actuator>
  <keyframe>
    <key name="home" qpos="0.5 0 0 0 0 0 1 0 0.1 1 0 0 0"/>
  </keyframe>
</mujoco>
